Workbook

Sheet Read Me
A1: John Sadler Plumbing & Heating: tracked keyword list (draft)
A3: Prepared | B3: 2026-10-15 by Francis Marc Uy for Andrew Silbernagel (task from #johnsadler, 2026-09-04). Draft for review before any Semrush changes.
A4: Purpose | B4: One keyword set mirrored across Surrey, White Rock and Langley, plus location-specific terms, with what to add to or remove from Semrush project 2824033.
A6: TABS
A7: Summary | B7: Counts by market and status (live formulas).
A8: Final Tracking List | B8: Every keyword to track after the changes (Keep + Add). Filter by Market or Service.
A9: Semrush Changes | B9: Only the Add and Remove rows, ready to action in Semrush. Mark "Done?" (yellow column) as you go.
A10: Skipped & Removed | B10: Everything dropped and why, so nothing disappears silently.
A11: Current Tracked (113) | B11: Snapshot of the existing Semrush list with positions (2026-09-29 to 2026-10-05) and the recommended action.
A12: Competitors | B12: Terms where hilltopplumbing.com outranks us (Semrush, 2026-10-05).
A14: RULES APPLIED
A15: Mirroring | B15: A service keyword is tracked in all 3 markets or none. Exceptions: location-specific terms (South Surrey, neighbourhoods) and national Navien/strata terms.
A16: Low volume | B16: A mirrored keyword is dropped when its 3 markets combined total under 30 searches/month (higher of the Keyword Planner and Semrush figures). One exception: "tankless water heater repair" is kept as a core Navien service (ranks #5 in Surrey). Easy to change if a different cut-off is preferred.
A17: Out of scope | B17: Abbotsford (no longer served) removed. Never-target list from keywords.md s.4 respected: no drains, faucets, toilets, propane/oil, new construction, fire installations, commercial, mobile homes, pools.
A18: Brand | B18: "best" keywords are track-only and never used in copy. AC and heat pump repair terms are allowed since 2026-08-20, but the live AC/heat pump pages still say "installs only" and need fixing first.
A20: SOURCES & DATA NOTES
A21: Tracking data | B21: Semrush Position Tracking project 2824033, pulled 2026-10-06 (one 113-keyword campaign; per-market campaigns not visible via API, confirm in the Semrush UI).
A22: KP volume | B22: Google Ads Keyword Planner, Canada, average monthly searches (Oct 2025 to Sept 2026), pulled 2026-10-15. Blank = Planner grouped the term with a close variant (e.g. plumber surrey / plumbers surrey).
A23: Semrush volume | B23: Volume recorded in the Semrush tracking campaign (existing keywords only). Fresh Semrush volumes for new keywords were not pulled: the Semrush account is out of API units.
A24: Gap / competitor terms | B24: keywords.md s.5 (Hilltop gap, 2024 KW Research sheet, Client Overview 2026, Oct 2023 meeting notes).
A25: Not included yet | B25: GSC tab: no agency Search Console access for johnsadler.ca found. GBP tab: GBP search-term insights not pulled. Both should be added before this is final.

Sheet Summary
A1: Summary
A3: Market | B3: Keep | C3: Add | D3: Total to track | E3: Remove | F3: Skip
A4: Surrey | B4: =COUNTIFS('Final Tracking List'!$A:$A,$A4,'Final Tracking List'!$D:$D,"Keep") | C4: =COUNTIFS('Final Tracking List'!$A:$A,$A4,'Final Tracking List'!$D:$D,"Add") | D4: =B4+C4 | E4: =COUNTIFS('Skipped & Removed'!$B:$B,$A4,'Skipped & Removed'!$A:$A,"Remove") | F4: =COUNTIFS('Skipped & Removed'!$B:$B,$A4,'Skipped & Removed'!$A:$A,"Skip")
A5: White Rock | B5: =COUNTIFS('Final Tracking List'!$A:$A,$A5,'Final Tracking List'!$D:$D,"Keep") | C5: =COUNTIFS('Final Tracking List'!$A:$A,$A5,'Final Tracking List'!$D:$D,"Add") | D5: =B5+C5 | E5: =COUNTIFS('Skipped & Removed'!$B:$B,$A5,'Skipped & Removed'!$A:$A,"Remove") | F5: =COUNTIFS('Skipped & Removed'!$B:$B,$A5,'Skipped & Removed'!$A:$A,"Skip")
A6: Langley | B6: =COUNTIFS('Final Tracking List'!$A:$A,$A6,'Final Tracking List'!$D:$D,"Keep") | C6: =COUNTIFS('Final Tracking List'!$A:$A,$A6,'Final Tracking List'!$D:$D,"Add") | D6: =B6+C6 | E6: =COUNTIFS('Skipped & Removed'!$B:$B,$A6,'Skipped & Removed'!$A:$A,"Remove") | F6: =COUNTIFS('Skipped & Removed'!$B:$B,$A6,'Skipped & Removed'!$A:$A,"Skip")
A7: All (no location) | B7: =COUNTIFS('Final Tracking List'!$A:$A,$A7,'Final Tracking List'!$D:$D,"Keep") | C7: =COUNTIFS('Final Tracking List'!$A:$A,$A7,'Final Tracking List'!$D:$D,"Add") | D7: =B7+C7 | E7: =COUNTIFS('Skipped & Removed'!$B:$B,$A7,'Skipped & Removed'!$A:$A,"Remove") | F7: =COUNTIFS('Skipped & Removed'!$B:$B,$A7,'Skipped & Removed'!$A:$A,"Skip")
A8: Abbotsford | B8: =COUNTIFS('Final Tracking List'!$A:$A,$A8,'Final Tracking List'!$D:$D,"Keep") | C8: =COUNTIFS('Final Tracking List'!$A:$A,$A8,'Final Tracking List'!$D:$D,"Add") | D8: =B8+C8 | E8: =COUNTIFS('Skipped & Removed'!$B:$B,$A8,'Skipped & Removed'!$A:$A,"Remove") | F8: =COUNTIFS('Skipped & Removed'!$B:$B,$A8,'Skipped & Removed'!$A:$A,"Skip")
A9: Total | B9: =SUM(B4:B8) | C9: =SUM(C4:C8) | D9: =SUM(D4:D8) | E9: =SUM(E4:E8) | F9: =SUM(F4:F8)
A11: Currently tracked in Semrush | D11: =COUNTA('Current Tracked (113)'!B:B)-1
A12: Tracked after changes | D12: =D9
A14: Low-volume threshold (3 markets combined, searches/mo): 30. See Read Me.

Sheet Final Tracking List
A1: Market | B1: Service | C1: Keyword | D1: Status | E1: Reason | F1: Source | G1: KP volume | H1: Semrush volume | I1: Pos. 10-05 | J1: Current ranking URL | K1: Target page | L1: Notes
A2: Surrey | B2: Air conditioning | C2: ac repair surrey | D2: Add | E2: New service / gap term | F2: Gap list (keywords.md s.5): client service change 2026-08-20 | G2: 110 | K2: /services/heating-cooling/air-conditioning/ | L2: AC / heat pump repair offered since 2026-08-20; live AC and heat pump pages still say "installs only" (fix before pushing these).
A3: Surrey | B3: Air conditioning | C3: air conditioning repair surrey | D3: Keep | F3: Semrush tracking (project 2824033) | G3: 110 | H3: 20 | K3: /services/heating-cooling/air-conditioning/ | L3: AC / heat pump repair offered since 2026-08-20; live AC and heat pump pages still say "installs only" (fix before pushing these).
A4: Surrey | B4: Air conditioning | C4: surrey air conditioning | D4: Keep | F4: Semrush tracking (project 2824033) | H4: 110 | I4: 41 | J4: /services/heating-cooling/air-conditioning/ | K4: /services/heating-cooling/air-conditioning/
A5: Surrey | B5: Air conditioning | C5: air conditioner surrey | D5: Keep | F5: Semrush tracking (project 2824033) | G5: 20 | H5: 110 | I5: 22 | J5: /services/heating-cooling/air-conditioning/ | K5: /services/heating-cooling/air-conditioning/
A6: Surrey | B6: Air conditioning | C6: hvac repair surrey | D6: Add | E6: New service / gap term | F6: Gap list (keywords.md s.5): client service change 2026-08-20 | G6: 20 | K6: /services/heating-cooling/air-conditioning/ | L6: AC / heat pump repair offered since 2026-08-20; live AC and heat pump pages still say "installs only" (fix before pushing these). Residential only; no commercial HVAC.
A7: Surrey | B7: Boilers | C7: boiler repair surrey | D7: Keep | F7: Semrush tracking (project 2824033) | G7: 40 | H7: 30 | I7: 14 | J7: /surrey-boiler-services/ | K7: /services/heating-cooling/boiler-repair/
A8: Surrey | B8: Boilers | C8: boiler installation surrey | D8: Keep | F8: Semrush tracking (project 2824033) | G8: 20 | H8: 10 | I8: 2 | J8: / | K8: /boiler-replacement/
A9: Surrey | B9: Boilers | C9: boiler services surrey | D9: Keep | F9: Semrush tracking (project 2824033) | G9: 10 | H9: 20 | I9: 1 | J9: /surrey-boiler-services/ | K9: /surrey-boiler-services/
A10: Surrey | B10: Furnaces | C10: furnace repair surrey | D10: Keep | F10: Semrush tracking (project 2824033) | G10: 390 | H10: 590 | I10: 31 | J10: /services/heating-cooling/furnace-repair/ | K10: /services/heating-cooling/furnace-repair/
A11: Surrey | B11: Furnaces | C11: furnace services surrey | D11: Keep | F11: Semrush tracking (project 2824033) | H11: 110 | I11: 19 | J11: /services/heating-cooling/furnace-repair/ | K11: /services/heating-cooling/furnace-repair/
A12: Surrey | B12: Furnaces | C12: furnace installation surrey | D12: Keep | F12: Semrush tracking (project 2824033) | G12: 70 | H12: 20 | I12: 13 | J12: /services/heating-cooling/furnace-installation/ | K12: /services/heating-cooling/furnace-installation/
A13: Surrey | B13: Furnaces | C13: furnace service surrey | D13: Keep | F13: Semrush tracking (project 2824033) | G13: 50 | H13: 110 | I13: 8 | J13: /services/heating-cooling/furnace-repair/ | K13: /services/heating-cooling/furnace-repair/
A14: Surrey | B14: Furnaces | C14: furnace replacement surrey | D14: Add | E14: New service / gap term | F14: Gap list (keywords.md s.5): KW Research sheet 2024 / Client Overview 2026 | G14: 20 | K14: /services/heating-cooling/furnace-installation/
A15: Surrey | B15: Furnaces | C15: furnace maintenance surrey | D15: Add | E15: New service / gap term | F15: Gap list (keywords.md s.5): KW Research sheet 2024 / Client Overview 2026 | G15: 10 | K15: /services/heating-cooling/furnace-repair/
A16: Surrey | B16: Furnaces | C16: furnace repair south surrey | D16: Keep | E16: Location-specific (South Surrey, where the business is based) | F16: Semrush tracking (project 2824033) | G16: 10 | H16: 20 | I16: 4 | J16: /services/heating-cooling/furnace-repair/ | K16: /services/heating-cooling/furnace-repair/
A17: Surrey | B17: Gas fitting | C17: gas fitter surrey | D17: Keep | F17: Semrush tracking (project 2824033) | G17: 70 | H17: 70 | I17: 1 | J17: / | K17: /services/gas-fitting/
A18: Surrey | B18: Gas fitting | C18: gas line installation surrey | D18: Keep | F18: Semrush tracking (project 2824033) | G18: 10 | H18: 10 | I18: 1 | J18: / | K18: /services/gas-fitting/
A19: Surrey | B19: Heat pumps | C19: heat pump installation surrey | D19: Keep | F19: Semrush tracking (project 2824033) | G19: 70 | H19: 30 | I19: 11 | J19: /services/heating-cooling/heat-pumps/ | K19: /services/heating-cooling/heat-pumps/
A20: Surrey | B20: Heat pumps | C20: heat pump repair surrey | D20: Add | E20: New service / gap term | F20: Gap list (keywords.md s.5): client service change 2026-08-20 | G20: 30 | K20: /services/heating-cooling/heat-pumps/ | L20: AC / heat pump repair offered since 2026-08-20; live AC and heat pump pages still say "installs only" (fix before pushing these).
A21: Surrey | B21: Heating & cooling (general) | C21: hvac surrey | D21: Add | E21: New service / gap term | F21: Gap list (keywords.md s.5): KW Research sheet 2024 / Client Overview 2026 | G21: 480 | K21: / | L21: Residential only; no commercial HVAC.
A22: Surrey | B22: Heating & cooling (general) | C22: plumbing and heating surrey | D22: Keep | F22: Semrush tracking (project 2824033) | G22: 90 | H22: 90 | I22: 26 | J22: / | K22: /
A23: Surrey | B23: Heating & cooling (general) | C23: heating installation surrey | D23: Keep | F23: Semrush tracking (project 2824033) | G23: 10 | H23: 10 | I23: 26 | J23: / | K23: /
A24: Surrey | B24: Heating & cooling (general) | C24: heating service surrey | D24: Keep | F24: Semrush tracking (project 2824033) | H24: 10 | I24: 32 | J24: / | K24: /
A25: Surrey | B25: Hot water tanks | C25: hot water tank replacement surrey | D25: Keep | F25: Semrush tracking (project 2824033) | G25: 50 | H25: 30 | I25: 6 | J25: /services/plumbing/hot-water-tanks/ | K25: /services/plumbing/hot-water-tanks/
A26: Surrey | B26: Hot water tanks | C26: hot water tank repair surrey | D26: Keep | F26: Semrush tracking (project 2824033) | G26: 30 | H26: 20 | I26: 5 | J26: /services/plumbing/hot-water-tanks/ | K26: /services/plumbing/hot-water-tanks/
A27: Surrey | B27: Hot water tanks | C27: hot water tank installation surrey | D27: Keep | F27: Semrush tracking (project 2824033) | G27: 20 | H27: 10 | I27: 5 | J27: /services/plumbing/hot-water-tanks/ | K27: /services/plumbing/hot-water-tanks/
A28: Surrey | B28: Hot water tanks | C28: water heater repair surrey | D28: Add | E28: New service / gap term | F28: Gap list (keywords.md s.5): KW Research sheet 2024 / Client Overview 2026 | G28: 20 | K28: /services/plumbing/hot-water-tanks/
A29: Surrey | B29: Hot water tanks | C29: hot water tank services surrey | D29: Keep | F29: Semrush tracking (project 2824033) | G29: 10 | H29: 10 | I29: 5 | J29: /services/plumbing/hot-water-tanks/ | K29: /services/plumbing/hot-water-tanks/
A30: Surrey | B30: Hot water tanks | C30: water heater south surrey | D30: Keep | E30: Location-specific (South Surrey, where the business is based) | F30: Semrush tracking (project 2824033) | G30: 10 | H30: 10 | I30: 3 | J30: / | K30: /services/plumbing/hot-water-tanks/
A31: Surrey | B31: Plumbing (general) | C31: plumber in surrey | D31: Keep | F31: Semrush tracking (project 2824033) | G31: 2400 | H31: 1300 | I31: 12 | J31: / | K31: /
A32: Surrey | B32: Plumbing (general) | C32: plumbers in surrey bc | D32: Keep | F32: Semrush tracking (project 2824033) | G32: 2400 | H32: 210 | I32: 10 | J32: / | K32: /
A33: Surrey | B33: Plumbing (general) | C33: plumber surrey | D33: Keep | F33: Semrush tracking (project 2824033) | H33: 1300 | I33: 14 | J33: / | K33: /
A34: Surrey | B34: Plumbing (general) | C34: plumbers surrey | D34: Keep | F34: Semrush tracking (project 2824033) | H34: 1300 | I34: 15 | J34: / | K34: /
A35: Surrey | B35: Plumbing (general) | C35: surrey plumbing | D35: Keep | F35: Semrush tracking (project 2824033) | H35: 1300 | K35: /
A36: Surrey | B36: Plumbing (general) | C36: plumbing company surrey | D36: Keep | F36: Semrush tracking (project 2824033) | G36: 260 | H36: 110 | I36: 17 | J36: / | K36: /
A37: Surrey | B37: Plumbing (general) | C37: plumber south surrey | D37: Keep | E37: Location-specific (South Surrey, where the business is based) | F37: Semrush tracking (project 2824033) | G37: 210 | H37: 170 | J37: / | K37: / | L37: Hilltop ranks #6-7 here; we are not in the top 100.
A38: Surrey | B38: Plumbing (general) | C38: plumbers surrey bc | D38: Keep | F38: Semrush tracking (project 2824033) | H38: 210 | I38: 10 | J38: / | K38: /
A39: Surrey | B39: Plumbing (general) | C39: plumbing services surrey | D39: Keep | F39: Semrush tracking (project 2824033) | G39: 170 | H39: 90 | I39: 17 | J39: / | K39: /
A40: Surrey | B40: Plumbing (general) | C40: south surrey plumbing | D40: Keep | E40: Location-specific (South Surrey, where the business is based) | F40: Semrush tracking (project 2824033) | H40: 170 | K40: / | L40: Hilltop ranks #6-7 here; we are not in the top 100.
...

Sheet Semrush Changes
A1: Action | B1: Market | C1: Keyword | D1: Why | E1: KP volume | F1: Semrush volume | G1: Pos. 10-05 | H1: Done?
A2: Add to Semrush | B2: Surrey | C2: ac repair surrey | D2: New service / gap term | E2: 110
A3: Add to Semrush | B3: Surrey | C3: hvac repair surrey | D3: New service / gap term | E3: 20
A4: Add to Semrush | B4: Surrey | C4: furnace replacement surrey | D4: New service / gap term | E4: 20
A5: Add to Semrush | B5: Surrey | C5: furnace maintenance surrey | D5: New service / gap term | E5: 10
A6: Add to Semrush | B6: Surrey | C6: heat pump repair surrey | D6: New service / gap term | E6: 30
A7: Add to Semrush | B7: Surrey | C7: hvac surrey | D7: New service / gap term | E7: 480
A8: Add to Semrush | B8: Surrey | C8: water heater repair surrey | D8: New service / gap term | E8: 20
A9: Add to Semrush | B9: Surrey | C9: plumber cloverdale | D9: Location-specific: client priority area | E9: 20
A10: Add to Semrush | B10: Surrey | C10: plumber guildford | D10: Location-specific: client priority area | E10: 10
A11: Add to Semrush | B11: Surrey | C11: cloverdale plumbing | D11: Location-specific: client priority area
A12: Add to Semrush | B12: White Rock | C12: white rock air conditioning | D12: Mirrors the same keyword in all 3 markets | E12: 10
A13: Add to Semrush | B13: White Rock | C13: ac repair white rock | D13: New service / gap term
A14: Add to Semrush | B14: White Rock | C14: air conditioning repair white rock | D14: Mirrors the same keyword in all 3 markets | E14: 0
A15: Add to Semrush | B15: White Rock | C15: hvac repair white rock | D15: New service / gap term | E15: 0
A16: Add to Semrush | B16: White Rock | C16: boiler services white rock | D16: Mirrors the same keyword in all 3 markets | E16: 0
A17: Add to Semrush | B17: White Rock | C17: furnace maintenance white rock | D17: New service / gap term | E17: 0
A18: Add to Semrush | B18: White Rock | C18: furnace replacement white rock | D18: New service / gap term | E18: 0
A19: Add to Semrush | B19: White Rock | C19: furnace services white rock | D19: Mirrors the same keyword in all 3 markets
A20: Add to Semrush | B20: White Rock | C20: heat pump repair white rock | D20: New service / gap term | E20: 0
A21: Add to Semrush | B21: White Rock | C21: hvac white rock | D21: New service / gap term | E21: 10
A22: Add to Semrush | B22: White Rock | C22: hot water tank installation white rock | D22: Mirrors the same keyword in all 3 markets | E22: 0
A23: Add to Semrush | B23: White Rock | C23: water heater repair white rock | D23: New service / gap term | E23: 0
A24: Add to Semrush | B24: White Rock | C24: best plumber white rock | D24: Mirrors the same keyword in all 3 markets | E24: 0
A25: Add to Semrush | B25: White Rock | C25: plumbing company white rock | D25: Mirrors the same keyword in all 3 markets | E25: 0
A26: Add to Semrush | B26: White Rock | C26: tankless water heater installation white rock | D26: Mirrors the same keyword in all 3 markets | E26: 0
A27: Add to Semrush | B27: White Rock | C27: tankless water heater repair white rock | D27: Mirrors the same keyword in all 3 markets | E27: 0
A28: Add to Semrush | B28: Langley | C28: ac repair langley | D28: New service / gap term | E28: 40
A29: Add to Semrush | B29: Langley | C29: hvac repair langley | D29: New service / gap term | E29: 10
A30: Add to Semrush | B30: Langley | C30: langley air conditioning | D30: Mirrors the same keyword in all 3 markets
A31: Add to Semrush | B31: Langley | C31: furnace replacement langley | D31: New service / gap term | E31: 50
A32: Add to Semrush | B32: Langley | C32: furnace maintenance langley | D32: New service / gap term | E32: 40
A33: Add to Semrush | B33: Langley | C33: heat pump repair langley | D33: New service / gap term | E33: 10
A34: Add to Semrush | B34: Langley | C34: hvac langley | D34: New service / gap term | E34: 210
A35: Add to Semrush | B35: Langley | C35: water heater repair langley | D35: New service / gap term | E35: 10
A36: Add to Semrush | B36: Langley | C36: plumber fort langley | D36: Location-specific: client priority area | E36: 10
A37: Add to Semrush | B37: Langley | C37: plumber willoughby | D37: Location-specific: client priority area | E37: 10
A38: Add to Semrush | B38: All (no location) | C38: navien tankless repair | D38: National term; already ranks about #10-14 on /services/navien/ | E38: 1600
A39: Add to Semrush | B39: All (no location) | C39: navien tankless water heater repair | D39: National term; already ranks about #10-14 on /services/navien/ | E39: 1600
A40: Add to Semrush | B40: All (no location) | C40: navien service | D40: National term; already ranks about #10-14 on /services/navien/ | E40: 20
...

Sheet Skipped & Removed
A1: Status | B1: Market | C1: Keyword | D1: Reason | E1: Source | F1: KP volume | G1: Semrush volume | H1: Pos. 10-05 | I1: Current ranking URL
A2: Remove | B2: Surrey | C2: air conditioning services surrey | D2: Low volume: 3 markets combined = 20/mo (under 30) | E2: Semrush tracking (project 2824033) | F2: 10 | G2: 10 | H2: 54 | I2: /services/heating-cooling/air-conditioning/
A3: Remove | B3: Surrey | C3: best plumbers in surrey | D3: Low volume: 3 markets combined = 20/mo (under 30) | E3: Semrush tracking (project 2824033) | G3: 20 | H3: 7 | I3: /
A4: Remove | B4: Surrey | C4: gas line installation services surrey | D4: Low volume: 3 markets combined = 10/mo (under 30) | E4: Semrush tracking (project 2824033) | F4: 10 | G4: 10 | H4: 4 | I4: /services/gas-fitting/
A5: Remove | B5: Surrey | C5: heating services surrey | D5: Low volume: 3 markets combined = 20/mo (under 30) | E5: Semrush tracking (project 2824033) | F5: 10 | G5: 10 | H5: 17 | I5: /
A6: Remove | B6: Surrey | C6: plumbing and heating company surrey | D6: Low volume: 3 markets combined = 20/mo (under 30) | E6: Semrush tracking (project 2824033) | F6: 10 | G6: 10 | H6: 4 | I6: /
A7: Remove | B7: Surrey | C7: tankless water heater maintenance surrey | D7: Low volume: 3 markets combined = 20/mo (under 30) | E7: Semrush tracking (project 2824033) | F7: 10 | G7: 10 | H7: 11 | I7: /services/plumbing/tankless-water-heaters/
A8: Remove | B8: Langley | C8: air conditioning services langley | D8: Low volume: 3 markets combined = 20/mo (under 30) | E8: Semrush tracking (project 2824033) | F8: 10 | G8: 10
A9: Remove | B9: Langley | C9: heating services langley | D9: Low volume: 3 markets combined = 20/mo (under 30) | E9: Semrush tracking (project 2824033) | F9: 10 | G9: 10 | H9: 66 | I9: /langley-plumbing-and-heating/
A10: Remove | B10: Langley | C10: plumbing and heating company langley | D10: Low volume: 3 markets combined = 20/mo (under 30) | E10: Semrush tracking (project 2824033) | F10: 10 | G10: 10
A11: Remove | B11: Langley | C11: tankless water heater maintenance langley | D11: Low volume: 3 markets combined = 20/mo (under 30) | E11: Semrush tracking (project 2824033) | F11: 10 | G11: 10 | H11: 34 | I11: /services/plumbing/hot-water-tanks/
A12: Remove | B12: All (no location) | C12: fortis rebates | D12: Informational, not a service; FortisBC co-op dropped 2025-09-02. Keep only if the rebate page is a deliberate lead magnet (confirm with Andrew). | E12: Semrush tracking (project 2824033) | F12: 1000 | G12: 2400 | H12: 59 | I12: /fortisbc-rebates/
A13: Remove | B13: Abbotsford | C13: boiler repair abbotsford | D13: Abbotsford is no longer served (Client Overview, Sept 2026) | E13: Semrush tracking (project 2824033) | F13: 10 | G13: 10 | H13: 46 | I13: /services/heating-cooling/boiler-repair/
A14: Remove | B14: Abbotsford | C14: furnace abbotsford | D14: Abbotsford is no longer served (Client Overview, Sept 2026) | E14: Semrush tracking (project 2824033) | F14: 10 | G14: 20
A15: Remove | B15: Abbotsford | C15: furnace maintenance abbotsford | D15: Abbotsford is no longer served (Client Overview, Sept 2026) | E15: Semrush tracking (project 2824033) | F15: 10 | G15: 10
A16: Remove | B16: Abbotsford | C16: furnace repair abbotsford | D16: Abbotsford is no longer served (Client Overview, Sept 2026) | E16: Semrush tracking (project 2824033) | F16: 90 | G16: 170
A17: Remove | B17: Abbotsford | C17: hot water tank abbotsford | D17: Abbotsford is no longer served (Client Overview, Sept 2026) | E17: Semrush tracking (project 2824033) | F17: 20 | G17: 20
A18: Remove | B18: Abbotsford | C18: plumber abbotsford | D18: Abbotsford is no longer served (Client Overview, Sept 2026) | E18: Semrush tracking (project 2824033) | F18: 880 | G18: 720
A19: Skip | B19: Surrey | C19: boiler maintenance surrey | D19: Low volume: 3 markets combined = 10/mo (under 30) | E19: Gap list (keywords.md s.5): KW Research sheet 2024 / Client Overview 2026 | F19: 10
A20: Skip | B20: Surrey | C20: heat pump service surrey | D20: Low volume: 3 markets combined = 20/mo (under 30) | E20: Gap list (keywords.md s.5): KW Research sheet 2024 / Client Overview 2026 | F20: 10
A21: Skip | B21: Surrey | C21: heating and cooling surrey | D21: Low volume: 3 markets combined = 20/mo (under 30) | E21: Gap list (keywords.md s.5): KW Research sheet 2024 / Client Overview 2026 | F21: 20
A22: Skip | B22: Surrey | C22: navien repair surrey | D22: Low volume: 3 markets combined = 0/mo (under 30) | E22: Gap list (keywords.md s.5): KW Research sheet 2024 / Client Overview 2026 | F22: 0
A23: Skip | B23: Surrey | C23: navien tankless water heater surrey | D23: Low volume: 3 markets combined = 0/mo (under 30) | E23: Gap list (keywords.md s.5): KW Research sheet 2024 / Client Overview 2026 | F23: 0
A24: Skip | B24: Surrey | C24: plumber crescent beach | D24: No measurable volume | E24: Client priority areas (Client Briefing 2026) | F24: 0
A25: Skip | B25: Surrey | C25: plumber grandview heights | D25: No measurable volume | E25: Client priority areas (Client Briefing 2026) | F25: 0
A26: Skip | B26: Surrey | C26: plumber morgan creek | D26: No measurable volume | E26: Client priority areas (Client Briefing 2026) | F26: 0
A27: Skip | B27: Surrey | C27: plumber ocean park | D27: No measurable volume | E27: Client priority areas (Client Briefing 2026) | F27: 0
A28: Skip | B28: White Rock | C28: air conditioning services white rock | D28: Low volume: 3 markets combined = 20/mo (under 30) | E28: Mirror of tracked Surrey + Langley keyword | F28: 0
A29: Skip | B29: White Rock | C29: best plumbers in white rock | D29: Low volume: 3 markets combined = 20/mo (under 30) | E29: Mirror of tracked Surrey keyword | F29: 0
A30: Skip | B30: White Rock | C30: boiler maintenance white rock | D30: Low volume: 3 markets combined = 10/mo (under 30) | E30: Gap list (keywords.md s.5): KW Research sheet 2024 / Client Overview 2026 | F30: 0
... A48: Skip | B48: All (no location) | C48: strata plumbing services | D48: Low volume | E48: Oct 2023 client meeting notes | F48: 10

Sheet Current Tracked (113)
A1: Group | B1: Keyword | C1: Pos. 10-05 | D1: Pos. 09-29 | E1: 7-day change | F1: 30-day change | G1: Semrush volume | H1: KP volume | I1: Ranking URL | J1: Recommended action | K1: Why
A2: Surrey | B2: boiler services surrey | C2: 1 | D2: 2 | E2: +1 | F2: 0 | G2: 20 | H2: 10 | I2: /surrey-boiler-services/ | J2: Keep
A3: Surrey | B3: gas fitter surrey | C3: 1 | D3: 1 | E3: 0 | F3: 0 | G3: 70 | H3: 70 | I3: / | J3: Keep
A4: Surrey | B4: gas line installation surrey | C4: 1 | D4: 5 | E4: +4 | F4: +3 | G4: 10 | H4: 10 | I4: / | J4: Keep
A5: Surrey | B5: boiler installation surrey | C5: 2 | D5: 3 | E5: +1 | F5: +3 | G5: 10 | H5: 20 | I5: / | J5: Keep
A6: Surrey | B6: in floor heating surrey | C6: 2 | D6: 5 | E6: +3 | F6: -1 | G6: 10 | H6: 10 | I6: /services/plumbing/radiant-in-floor-heating/ | J6: Keep
A7: Surrey | B7: best plumber surrey | C7: 3 | D7: 2 | E7: -1 | F7: 0 | G7: 20 | H7: 70 | I7: / | J7: Keep
A8: Surrey | B8: radiant heating surrey | C8: 3 | D8: 4 | E8: +1 | F8: +1 | G8: 10 | H8: 10 | I8: / | J8: Keep
A9: Surrey | B9: water heater south surrey | C9: 3 | D9: 10 | E9: +7 | F9: +5 | G9: 10 | H9: 10 | I9: / | J9: Keep
A10: Surrey | B10: furnace repair south surrey | C10: 4 | D10: 1 | E10: -3 | F10: -3 | G10: 20 | H10: 10 | I10: /services/heating-cooling/furnace-repair/ | J10: Keep
A11: Surrey | B11: gas line installation services surrey | C11: 4 | D11: 2 | E11: -2 | F11: 0 | G11: 10 | H11: 10 | I11: /services/gas-fitting/ | J11: Remove | K11: Low volume: 3 markets combined = 10/mo (under 30)
A12: Surrey | B12: plumbing and heating company surrey | C12: 4 | D12: 23 | E12: +19 | F12: 0 | G12: 10 | H12: 10 | I12: / | J12: Remove | K12: Low volume: 3 markets combined = 20/mo (under 30)
A13: Surrey | B13: hot water tank installation surrey | C13: 5 | D13: 5 | E13: 0 | F13: 0 | G13: 10 | H13: 20 | I13: /services/plumbing/hot-water-tanks/ | J13: Keep
A14: Surrey | B14: hot water tank repair surrey | C14: 5 | D14: 5 | E14: 0 | F14: 0 | G14: 20 | H14: 30 | I14: /services/plumbing/hot-water-tanks/ | J14: Keep
A15: Surrey | B15: hot water tank services surrey | C15: 5 | D15: 5 | E15: 0 | F15: 0 | G15: 10 | H15: 10 | I15: /services/plumbing/hot-water-tanks/ | J15: Keep
A16: Surrey | B16: tankless water heater repair surrey | C16: 5 | D16: 6 | E16: +1 | F16: +2 | G16: 10 | H16: 10 | I16: /services/plumbing/tankless-water-heaters/ | J16: Keep
A17: Surrey | B17: hot water tank replacement surrey | C17: 6 | D17: 6 | E17: 0 | F17: +18 | G17: 30 | H17: 50 | I17: /services/plumbing/hot-water-tanks/ | J17: Keep
A18: Surrey | B18: best plumbers in surrey | C18: 7 | D18: 7 | E18: 0 | F18: 0 | G18: 20 | I18: / | J18: Remove | K18: Low volume: 3 markets combined = 20/mo (under 30)
A19: Surrey | B19: furnace service surrey | C19: 8 | D19: 16 | E19: +8 | F19: -3 | G19: 110 | H19: 50 | I19: /services/heating-cooling/furnace-repair/ | J19: Keep
A20: Surrey | B20: tankless water heater services surrey | C20: 9 | D20: 8 | E20: -1 | F20: +4 | G20: 10 | H20: 10 | I20: /services/plumbing/tankless-water-heaters/ | J20: Keep
A21: Surrey | B21: plumbers in surrey bc | C21: 10 | D21: 23 | E21: +13 | F21: 0 | G21: 210 | H21: 2400 | I21: / | J21: Keep
A22: Surrey | B22: plumbers surrey bc | C22: 10 | D22: 13 | E22: +3 | F22: +1 | G22: 210 | I22: / | J22: Keep
A23: Surrey | B23: heat pump installation surrey | C23: 11 | D23: 7 | E23: -4 | F23: -2 | G23: 30 | H23: 70 | I23: /services/heating-cooling/heat-pumps/ | J23: Keep
A24: Surrey | B24: tankless water heater maintenance surrey | C24: 11 | D24: 12 | E24: +1 | F24: -7 | G24: 10 | H24: 10 | I24: /services/plumbing/tankless-water-heaters/ | J24: Remove | K24: Low volume: 3 markets combined = 20/mo (under 30)
A25: Surrey | B25: plumber in surrey | C25: 12 | D25: 9 | E25: -3 | F25: -2 | G25: 1300 | H25: 2400 | I25: / | J25: Keep
A26: Surrey | B26: tankless water heater installation surrey | C26: 12 | D26: 24 | E26: +12 | F26: -5 | G26: 10 | H26: 20 | I26: /services/plumbing/tankless-water-heaters/ | J26: Keep
A27: Surrey | B27: furnace installation surrey | C27: 13 | D27: 20 | E27: +7 | F27: +8 | G27: 20 | H27: 70 | I27: /services/heating-cooling/furnace-installation/ | J27: Keep
A28: Surrey | B28: boiler repair surrey | C28: 14 | D28: 16 | E28: +2 | F28: +1 | G28: 30 | H28: 40 | I28: /surrey-boiler-services/ | J28: Keep
A29: Surrey | B29: plumber surrey | C29: 14 | D29: 14 | E29: 0 | F29: +11 | G29: 1300 | I29: / | J29: Keep
A30: Surrey | B30: plumbers surrey | C30: 15 | D30: 13 | E30: -2 | F30: -6 | G30: 1300 | I30: / | J30: Keep
A31: Surrey | B31: heating services surrey | C31: 17 | D31: 17 | E31: 0 | F31: -3 | G31: 10 | H31: 10 | I31: / | J31: Remove | K31: Low volume: 3 markets combined = 20/mo (under 30)
A32: Surrey | B32: plumbing company surrey | C32: 17 | D32: 17 | E32: 0 | F32: +4 | G32: 110 | H32: 260 | I32: / | J32: Keep
A33: Surrey | B33: plumbing services surrey | C33: 17 | D33: 27 | E33: +10 | F33: -4 | G33: 90 | H33: 170 | I33: / | J33: Keep
A34: Surrey | B34: furnace services surrey | C34: 19 | D34: 17 | E34: -2 | F34: -4 | G34: 110 | I34: /services/heating-cooling/furnace-repair/ | J34: Keep
A35: Surrey | B35: air conditioner surrey | C35: 22 | D35: 48 | E35: +26 | F35: +9 | G35: 110 | H35: 20 | I35: /services/heating-cooling/air-conditioning/ | J35: Keep
A36: Surrey | B36: heating installation surrey | C36: 26 | D36: 16 | E36: -10 | F36: -14 | G36: 10 | H36: 10 | I36: / | J36: Keep
A37: Surrey | B37: plumbing and heating surrey | C37: 26 | D37: 7 | E37: -19 | F37: -17 | G37: 90 | H37: 90 | I37: / | J37: Keep
A38: Surrey | B38: furnace repair surrey | C38: 31 | D38: 13 | E38: -18 | F38: -22 | G38: 590 | H38: 390 | I38: /services/heating-cooling/furnace-repair/ | J38: Keep
A39: Surrey | B39: heating service surrey | C39: 32 | D39: 15 | E39: -17 | F39: -16 | G39: 10 | I39: / | J39: Keep
A40: Surrey | B40: surrey air conditioning | C40: 41 | D40: 36 | E40: -5 | F40: -8 | G40: 110 | I40: /services/heating-cooling/air-conditioning/ | J40: Keep
...

Sheet Competitors
A1: Keyword | B1: Hilltop pos. | C1: Sadler pos. | D1: Volume | E1: Notes
A2: plumber white rock | B2: 1 | C2: 6 | D2: 390
A3: plumbers white rock | B3: 2 | C3: 9 | D3: 390
A4: plumber in white rock | B4: 2 | C4: 9 | D4: 390
A5: white rock plumbing | B5: 2 | C5: 6 | D5: 390
A6: furnace repair white rock | B6: 1 | C6: 32 | D6: 90
A7: plumber south surrey | B7: 7 | D7: 170 | E7: Sadler not in top 100
A8: south surrey plumbing | B8: 6 | D8: 170 | E8: Sadler not ranking
A10: hilltopplumbing.com outranks Sadler on 34 of 113 tracked terms (Semrush, 2026-10-05), mostly White Rock, where Hilltop holds #1 on 18. Volumes on this tab are Semrush campaign volumes.
A11: Other White Rock terms where Hilltop is #1: boiler repair, furnace installation, furnace service, gas fitter, gas line installation, heat pump installation, heating installation, heating service, hot water tank repair / replacement / services, in floor heating, plumbing services, tankless water heater services, air conditioner.
A12: Implication: White Rock has one location page while Langley has dedicated boiler and furnace pages. Feeds the location-strategy step.
A13: Full per-keyword Hilltop export not pulled (Semrush API units exhausted). Pull it from the Semrush UI to complete this tab.
